Workbook
Name _Hlk67577761: #REF!
Name _Hlk67577761: #REF!

Sheet Introduction
C8: TOOL | N8: Change log
C9: for preliminary assessment and notification form generator | N9: Date | O9: Version | P9: Explanation
C10: (NIS2@RO Tool) | N10: 45566 | O10: V0 | P10: Initial version (RO)
N11: 45299 | O11: V0.1 | P11: Updated version according to OUG no. 155/2024
C12: The preliminary evaluation and notification form generator tool (NIS2@RO Tool) is developed by the Romanian National Cyber Security Directorate (DNSC), based on the "NIS2 scope assessment" concept developed by the Belgian Cybersecurity Center (CCB). The NIS2@RO tool is useful for supporting entities in Romania in assessing if they fall within the scope of OUG No. 155/2024, approved with amendments and additions by Law No. 124/2025 and generating the notification form in order to submit it to DNSC for the purpose of registration in the Entities Register. After filling in the required data and info, the tool facilitates the generation of the notification form, at the user's request. Depending on the available transmission method, the form is sent, accompanied, where applicable, by additional documents, accepted and signed electronically. | N12: 45853 | O12: V0.2 | P12: Updated version in accordance with Law No. 124/2025
N13: 45876 | O13: V1.0 | P13: Final version (RO)
N14: 45898 | O14: V2.0 | P14: Update
N15: 45912 | O15: V2.1 | P15: Update
N16: 45915 | O16: V2.1 ENG | P16: First version (EN)
G19: TLP:GREEN

Sheet User instructions
O2: Version: | P2: =CONCATENATE(Introduction!O16,"_",Introduction!N16) -> V2.1 ENG_45915
C4: NOTIFICATION FORM GENERATOR AND PRELIMINARY ASSESSMENT TOOL (NIS2@RO Tool) User guide
C6: The Notification Form Generator and Preliminary Assessment Tool (NIS2@RO Tool) was developed by the Romanian National Cyber Security Directorate (DNSC).
C7: Based on OUG No. 155/2024, approved, with amendments and additions, by Law No. 124/2025, the DNSC has identified and managed 18 sectors, classified as sectors of high critical importance (11) and other sectors of critical importance (7). Sixteen subsectors (plus one identified by Law No. 294/2024) were also identified, namely 10 (plus one identified by Law No. 294/2024) for the first category of sectors (in Annex No. 1) and 6 for the second category (in Annex No. 2).
C8: FOR THE ASSESSMENT OF FALLING WITHIN THE SCOPE OF APPLICATION OF OUG NO. 155/2024 (APPROVED, WITH AMENDMENTS AND ADDITIONS, BY LAW NO. 124/2025) AND GENERATING THE NOTIFICATION FORM, ENTITIES IN ROMANIA SHALL MANDATORILY USE ONE OF THE TWO TOOLS DEVELOPED BY DNSC, PLATFORMANIS2.RO OR THE NIS2@RO TOOL.
C9: IN THE CASE OF THE NIS2@RO TOOL, ENTITIES AS DEFINED IN ARTICLE 4 LETTER F) OF OUG NO. 155/2024 (approved, with amendments and additions, by Law No. 124/2025) SHALL DOWNLOAD AND USE IT.
C10: The NIS2@RO Tool can be downloaded from the DNSC website, dnsc.ro or platformanis2.ro, and run locally. To run and use the tool, the entity must have Microsoft Excel.
C11: In order to assess whether it falls within the scope of OUG No. 155/2024 (approved, with amendments and additions, by Law No. 124/2025), the following steps are taken:
C12: Step 1. Entity identification
D13: §1. Filling in the entity's identification data
D14: Select the “/«Entity data»/” sheet and fill in the data and information about the entity, as required.
D15: Note:/. The data/information entered is mandatory and will be used to generate the notification form. It must be completed responsibly and in accordance with the requirements of the worksheet, using accurate and reliable information.
D16: §2. Running the assessment tool
D17: After filling in the entity identification data, proceed to assess whether it falls within the scope of the regulatory act, select the link (Entity assessment) on the right side of the assessment date or select the "Entity assessment" sheet.
C18: Step 2. Assessment of falling within the scope of application of OUG No. 155/2024 (approved, with amendments and additions, by Law No. 124/2025)
D19: §1. Fill in the details about the size of the entity
D20: Fill in the Entity size section, namely: Average annual number of employees, Annual net turnover, Total assets, and select the size of the entity from the available list. Please note! All three characteristics must be completed, except for the central public administration.
D21: Note: For more details on how these thresholds are calculated, check out Law No. 346 of July 14, 2004, on encouraging the establishment and development of small and medium-sized enterprises.
D22: §2. Filling in the services provided according to sectors/sub-sectors
D23: Fill in the section Data on services provided (by sector/subsector).
D24: All services provided shall be completed by selecting "Yes" corresponding to the type of entity (by sector and, where applicable, subsector).
D25: Based on the data entered, the tool will generate a number in the “/«Status of services provided»/” field, which corresponds to the number of services selected and provided by the entity.
D26: §3. Filling in specific data regarding the entity's relationship with Romania
D27: The section "Relationship of the entity with the Romanian state" is filled in.
D28: Depending on the data/information entered in the section DATA ON SERVICES PROVIDED (BY SECTOR/SUBSECTOR), certain fields in the section RELATIONSHIP OF THE ENTITY WITH THE ROMANIAN STATE are marked and must be completed. All marked fields in the section must be completed by selecting the "Yes" or "No" answer corresponding to each question.
D29: §4. Filling in data regarding the provision of services in the EU
D30: The section on the provision of services in the EU shall be completed.
... D34: The entity performing the assessment of compliance with the scope of OUG No. 155/2024 (approved, with amendments and additions, by Law No. 124/2025), depending on the services provided and the data and information provided, shall be required to answer all four questions in this section. All the relevant fields shall be completed as follows: "Yes" or "No" (9a and 9d); "High," "Medium," or "Low" (9b and 9c).
C36: Preliminary assessment
C37: After completing all the previous steps (§1 - §5), if all the required answers have been filled in correctly and in accordance with OUG No. 155/2024 (approved, with amendments and additions, by Law No. 124/2025), the NIS2 Tool generates a preliminary assessment, namely: Outside the scope (the entity is not required to apply the legislation transposing the NIS2 Directive); Important entity (the entity qualifies as an important entity); Essential entity (the entity qualifies as an essential entity).
C38: Warning! Regardless of the preliminary assessment generated by the NIS2@RO Tool, please submit the form to DNSC for confirmation of the entity's status. The preliminary assessment generated is intended to guide the user through the notification process.
C39: Warning! If you wish to reuse the tool, you must restore it to its initial state, i.e. reset all modified/populated information.
C40: To generate the notification form, proceed as follows:
C41: GENERATING THE NOTIFICATION FORM
C42: After finalizing the assessment process for compliance with the scope of OUG No. 155/2024 (approved, with amendments and additions, by Law No. 124/2025) and obtaining the preliminary assessment, the entity will generate the notification form, which will be sent to DNSC accompanied, where applicable, supporting documents (attached) in order to be registered in the Register of Entities. Select the link: Notification form, the form will be generated and then saved in PDF format. After approval and signing, it will be sent to DNSC accompanied, where applicable, by attached documents. The notification form is generated in PDF format and is not editable.
C43: Useful information
C44: 1st scenario. The entity is included in the scope of OUG No. 155/2024 (approved, with amendments and additions, by Law No. 124/2025) as an essential or important entity.
C45: In this scenario, you should proceed as follows: & register in the Register of Entities at DNSC (using as a method of transmitting information, as appropriate, on the PlatformaNIS2[.]ro platform, by email evidenta@dnsc[.]ro, at the DNSC headquarters at 22 Italiană Street, Sector 2, Bucharest, CP 020967 & applying the procedure and methods specified in the Requirements for the notification process for registration and the method of transmitting information, approved by DNSC Director Order No. 1/2020 & entities must open an account on PlatformaNIS2.ro and fill in all the data required for registration in the Register of Entities, regardless of the method of submitting the notification; & take measures to manage cybersecurity risks; & report significant incidents to the competent national authority on the PNRISC platform (pnrisc.dnsc[.]ro/); & cooperate with the competent authorities (at national and sectoral level).
C46: More information on NIS2 (namely Government Emergency Ordinance (OUG) No. 155/2024—approved, with amendments and additions, by Law No. 124/2025—subsequent acts, guides, guidelines, etc.) is available on the DNSC websites (dnsc[.]ro; platformanis2[.]ro).
C47: 2nd Scenario. The entity does not fall within the scope of Government Emergency Ordinance (OUG) No. 155/2024 (approved, with amendments and additions, by Law No. 124/2025).
...

Sheet Entity data
F2: =CONCATENATE("Versiunea: ",Introduction!O16,"_",Introduction!N16) -> Versiunea: V2.1 ENG_45915
C4: NIS2@RO Tool DATA AND INFORMATION ABOUT THE ENTITY
C6: Enter the requested data and information. It is mandatory to enter all the requested data and information to ensure the assessment process for compliance with the scope of OUG No. 155/2024 (approved, with amendments and additions, by Law No. 124/2025) and to generate the notification form.
C7: Mandatory fields
C8: Fill in as appropriate
C10: GENERAL INFORMATION
C11: Entity identification data | F11: Generate the Notification Form! After completing the assessment of the scope of application, generate the “Notification Form” from the “Entity Assessment” sheet, save it in PDF format, and then sign it.
C12: Name of the entity
C13: Unique Identification Code (CUI)
C14: National registration number
C15: Entity contact details
C16: Country
C17: County
C18: City/Town
C19: District | D19: 4
C20: Street
C21: Number
C22: Block/building, other
C23: Entrance/staircase/section, other
C24: Floor
C25: Apartment/office/room, other
C26: Postal code
C27: Email address
C28: Website URL
C29: Telephone number
C30: Mobile phone number
C31: Data regarding the activity carried out by the entity
... C36: Informations regarding the person responsible for cybersecurity
C37: Select | D37: Is there a designated person responsible for cybersecurity at the time of filling out this form?
C38: Surname
C39: First name
C40: Role
C41: Email address
C42: Mobile phone number
C43: Details regarding permanent means of contact and the person responsible for monitoring them
C44: The person responsible for monitoring
C45: Select | D45: The person responsible for monitoring is the same as the person responsible for cybersecurity
C46: Last name
C47: First name
C48: Role
...

Sheet Entity assessment
D2: =CONCATENATE("Version: ",Introduction!O14,"_",Introduction!N14) -> Version: V2.0_45898
C4: PRELIMINARY ASSESSMENT AND NOTIFICATION FORM GENERATOR (NIS2@RO Tool)
C5: The following questions are intended to help entities determine whether the provisions of OUG No. 155/2024 (approved, with amendments and additions, by Law No. 124/2025) apply to them. Depending on the size, services provided and, where applicable, the criteria set out in Article 9 of OUG No. 155/2024 (approved, with amendments and additions, by Law No. 124/2025), an assessment is made as to whether OUG No. 155/2024 applies to the entity and, where applicable, whether it is an essential or important entity, in which case it is required to notify the DNSC for registration in the Register of Entities. The notification form is generated upon completion of the assessment. Please note! The NIS2@RO tool only generates a PRELIMINARY ASSESSMENT regarding the classification of entities as essential, important, or not subject to the provisions of OUG No. 155/2024 (approved, with amendments and additions, by Law No. 124/2025). | D5: More information about OUG No. 155/2024 (NIS2) can be found here
C9: ENTITY SIZE | D9: (i) Additional information
C10: Please enter the data regarding the size of the entity and the size category to which your entity belongs.
C11: In order to calculate the data to be taken into account for setting thresholds, an entity must first determine whether it is: a) an autonomous enterprise; b) a partner enterprise; c) a related enterprise. Please note: Art. 4 ind. 5 of Law No. 346/2004 does not apply.
C12: The value corresponding to turnover and total assets is expressed in euro currency. In the notification process, you will attach the documents specified in Article 7 of Law No. 346/2004 to the notification form. The size applicable to the entity is selected exclusively in accordance with the provisions of Law No. 346 of July 14, 2004, on stimulating the establishment and development of small and medium-sized enterprises, as amended and complemented (link below).
C13: Link to Law No. 346 of July 14, 2004, on stimulating the establishment and development of small and medium-sized enterprises.
C14: Link to the European Commission's "User Guide on the Definition of SMEs."
C15: Link to the European Commission's SME self-assessment tool.
C17: Average annual number of employees:
C18: Annual turnover (EUR):
C19: Balance Sheet (EUR):
C20: The data you entered indicates that you have the following size: | D20: =IF(OR(D17="", D18="", D19=""), "Insufficient data", IF(AND(D17<=49, OR(D18<=10000000, D19<=10000000)), "Small and micro", IF(AND(D17<=249, OR(D18<=50000000, D19<=43000000)), "Medium", IF(OR(D17>=250, D18>50000000, D19>43000000), "Large", "")))) -> Insufficient data
C21: Size of the entity according to Law No. 346/2004 (except for Central Public Administration) | D21: Select
C22: =IF(OR(ISBLANK(D18), ISBLANK(D17), ISBLANK(D19), D21="Select"), Liste!F6, "All the entity size-specific data has been filled in. Continue with the assessment process!") -> Please fill in all 3 criteria that determine the size of the entity and select the size that corresponds to your entity.
C24: DATA ON SERVICES PROVIDED (BY SECTOR/SUBSECTOR)
C26: Please select all services provided (by sector/sub-sector) from those listed below that correspond to the service provided by the entity.
C28: SECTORS OF HIGH CRITICALITY
C29: ENERGY
C30: Electricity
C31: Electricity undertakings | D31: No
C32: Distribution system operators | D32: No
C33: Transmission system operators | D33: No
C34: Electricity producers | D34: No
C35: Nominated electricity market operators | D35: No
C36: Electricity market participants | D36: No
C37: Operators of a recharging point | D37: No
C38: Economic operators, concessionaires and the developer of the offshore wind turbine | D38: No
C39: District heating and cooling
C40: Operators of district heating or district cooling | D40: No
C41: Oil
C42: Operators of oil transmission pipelines | D42: No
C43: Operators of oil production, refining and treatment facilities, storage and transmission | D43: No
C44: Central stockholding entities | D44: No
C45: Gas
C46: Natural gas supply undertakings | D46: No
C47: Distribution system operators | D47: No
C48: Transmission system operators | D48: No
C49: Storage system operators | D49: No
...

Sheet Notification form
C3: NOTIFICATION FORM
C6: GENERAL INFORMATION
C7: Entity identification data
C8: ='Entity data'!C12 -> Name of the entity
C9: =IF('Entity data'!D12="","",'Entity data'!D12)
C10: =CONCATENATE('Entity data'!C13,": ",'Entity data'!D13) -> Unique Identification Code (CUI):
C11: =CONCATENATE('Entity data'!C14,": ",'Entity data'!D14) -> National registration number:
C12: Entity contact details
C13: ="Headquarters address: " & IF('Entity data'!D16<>"", 'Entity data'!C16 & ": " & 'Entity data'!D16 & "; ", "") & IF('Entity data'!D20<>"", 'Entity data'!D20 & ", ", "") & IF('Entity data'!D21<>"", "no. " & 'Entity data'!D21 & ", ", "") & IF('Entity data'!D22<>"", "building: " & 'Entity data'!D22 & ", ", "") & IF('Entity data'!D23<>"", "entrance: " & 'Entity data'!D23 & ", ", "") & IF('Entity data'!D24<>"", "floor: " & 'Entity data'!D24 & ", ", "") & IF('Entity data'!D25<>"", "room: " & 'Entity data'!D25 & ", ", "") & IF('Entity data'!D18="Bucharest", IF(AND('Entity data'!C19<>"", 'Entity data'!D19<>""), 'Entity data'!C19 & " " & 'Entity data'!D19 & ", ", "") & 'Entity data'!D18 & ", ", IF('Entity data'!D18<>"", 'Entity data'!D18 & ", ", "")) & IF(AND('Entity data'!D18<>"Bucharest", 'Entity data'!D17<>""), "County " & 'Entity data'!D17, "") -> Headquarters address:
C14: =CONCATENATE('Entity data'!C26,": ",'Entity data'!D26) -> Postal code:
C15: =CONCATENATE("Email address: ",'Entity data'!D27) -> Email address:
C16: =CONCATENATE("Website URL: ",'Entity data'!D28) -> Website URL:
C17: =CONCATENATE("Telephone number: ",'Entity data'!D29) -> Telephone number:
C18: =CONCATENATE("Mobile phone number: ",'Entity data'!D30) -> Mobile phone number:
C19: Data regarding the activity carried out by the entity
C20: =CONCATENATE("Main NACE code: ",'Entity data'!D32) -> Main NACE code:
C21: =CONCATENATE("Secondary NACE code/s: ",'Entity data'!D33) -> Secondary NACE code/s:
C23: SPECIFIC DATA
C24: Entity size data
C25: ='Entity assessment'!C17 -> Average annual number of employees: | D25: =IF('Entity assessment'!D17="","",'Entity assessment'!D17)
C26: ='Entity assessment'!C18 -> Annual turnover (EUR): | D26: =IF('Entity assessment'!D18="","",'Entity assessment'!D18)
C27: ='Entity assessment'!C19 -> Balance Sheet (EUR): | D27: =IF('Entity assessment'!D19="","",'Entity assessment'!D19)
C28: ='Entity assessment'!C21 -> Size of the entity according to Law No. 346/2004 (except for Central Public Administration) | D28: =IF('Entity assessment'!D20='Entity assessment'!D21, 'Entity assessment'!D21, 'Entity assessment'!D21 & " 🔴") -> Select 🔴
C31: Data on services provided
C32: Service-related sectors | D32: =IF(COUNTBLANK(C33:C37)=5,"",5-COUNTBLANK(C33:C37))
C33: {=IF(ISBLANK(Ajutor!H2:I6),"",Ajutor!H2:I6)}
C39: Sub-sectors (if applicable) | D39: =IF(COUNTBLANK(C40:C44)=5,"",5-COUNTBLANK(C40:C44))
C40: {=IF(ISBLANK(Ajutor!N2:O6),"",Ajutor!N2:O6)}
C46: Services provided (types of entities) | D46: =IF(COUNTBLANK(_xlfn.ANCHORARRAY(C47))=5,"",5-COUNTBLANK(_xlfn.ANCHORARRAY(C47))) -> -5
C47: {=IF(ISBLANK(Ajutor!B2:B11),"",Ajutor!B2:B11)} | D47: {=IF(ISBLANK(Ajutor!C2:C6),"",Ajutor!C2:C6)}
C58: Informations regarding the person responsible for cybersecurity
C59: ='Entity data'!D37 -> Is there a designated person responsible for cybersecurity at the time of filling out this form? | D59: ='Entity data'!C37 -> Select
C60: =CONCATENATE("Last name and first name: ",'Entity data'!D38," ",UPPER('Entity data'!D39)) -> Last name and first name:
C61: =CONCATENATE('Entity data'!C40, ": ", 'Entity data'!D40) -> Role:
C62: =CONCATENATE("Email address: ", 'Entity data'!D41) -> Email address:
C63: =CONCATENATE("Mobile phone number: ", 'Entity data'!D42) -> Mobile phone number:
C66: Details of permanent means of contact and the person responsible for monitoring them
C67: The person responsible for monitoring
C68: ='Entity data'!D45 -> The person responsible for monitoring is the same as the person responsible for cybersecurity | D68: ='Entity data'!C45 -> Select
C69: =CONCATENATE(UPPER('Entity data'!D46)," ",'Entity data'!D47)
...

Sheet Liste
J1: 1 | K1: 2 | L1: 3 | M1: 4 | N1: 5 | O1: 6 | Q1: 1 | R1: 2 | S1: 3 | T1: 4 | U1: 5
B2: Da/Nu | C2: Număr salariați | D2: Cifră de afaceri anuală | E2: Total Active anuale | F2: Dimensiunea companiei | G2: Rezultat | H2: Cod Rezultat | J2: JUDEȚ | K2: Reședință | L2: ID_JUD | M2: CODAR | N2: ID_JUD | O2: CP(2) | Q2: Nomenclator NIS2 | R2: ID Categorie | S2: ID Sector | T2: ID Subsector | U2: ID Tip Entitate | Y2: Dimensiunea companiei | Z2: Acronim | AA2: Cifra dimensiunii | AC2: Adevărat | AD2: Impact | AE2: Risc | AF2: Nivel | AG2: Dimensiunea | AH2: Importanță sector | AK2: CR | AL2: R | AP2: CODS | AQ2: SECTOARE NIS2 | AS2: CODSs | AT2: SUBSECTOARE NIS2
B3: Select | C3: Select | D3: Select | E3: Select | F3: Întreprindere mică sau microîntreprindere | G3: Vă rugăm să răspundeți la toate întrebările pentru a finaliza evaluarea. | H3: 6 | J3: Alba | K3: Alba-Iulia | L3: AB | M3: RO171 | N3: =MID(M3,4,2) -> 71 | O3: 51 | Q3: SECTORS OF HIGH CRITICALITY | R3: 1 | W3: DNSC vă sfătuiește să: & vă înregistrați, voluntar, pentru a fi alertați cu privire la potențialele amenințări și vulnerabilități din rețelele și sistemele informatice. & implementați Cadrul fundamental pentru securitate cibernetică, nivel BASIC, în vederea îmbunătățirii nivelul de securitate cibernetică al entității dumneavoastră. Cadrele fundamentale pentru securitate cibernetică (niveluri: BASIC, IMPORTANT și ESENȚIAL) se găsesc pe site-urile instituției (dnsc[.]ro și/sau platformanis2[.]ro). În plus, dacă sunteți furnizor sau prestator de servicii pentru o entitate NIS2 aceasta vă poate impune măsuri de securitate (suplimentare) ca parte a obligațiilor sale privind securitatea lanțului de aprovizionare. | Y3: Mică și micro | Z3: S | AA3: 1 | AC3: Select | AD3: Select | AE3: Select | AF3: Select | AG3: Select | AH3: Select | AJ3: L | AK3: E | AL3: I | AP3: 101 | AQ3: Energy | AS3: 1011 | AT3: Electricity
B4: Yes | C4: 0 - 49 | D4: < 10 million € | E4: < 10 million € | F4: Întreprindere mijlocie | G4: Out of scope | H4: 5 | J4: Arad | K4: Arad | L4: AR | M4: RO451 | N4: =MID(M4,4,2) -> 51 | O4: 31 | Q4: ENERGY | S4: 101 | W4: Aveți obligația de a: & vă înregistra în Registrul entităților la DNSC (folosind ca metodă de transmitere a informațiilor, după caz, pe PlatformaNIS2[.]ro, prin email nis@dnsc[.]ro, la sediu DNSC str. Italiană 22, sector 2, București, CP 020967 - aplicând procedura și modalitățile specificate în Cerințele privind procesul de notificare în vederea înregistrării și metoda de transmitere a informațiilor, aprobate prin ODDNSC nr. nnn/2025; & lua măsuri de gestionare a riscurilor de securitate cibernetică, prin aplicarea Cadrelor fundamentale pentru securitate cibernetică (niveluri: BASIC, IMPORTANT și ESENȚIAL), în funcție de rezultatul evaluării riscului entității - aplicând Metodologia de evaluare a nivelului de risc al entităților, aprobată prin ODDNSC nr. nnn/2025, respectiv Instrumentul ERENIS@RO; & raporta incidentele semnificative la autoritatea competentă națională pe platforma PNRISC (pnrisc.dnsc[.]ro/); & coopera cu autoritățile competente (la nivel național și sectorial), în special în ceea ce privește supravegherea (inclusiv evaluarea periodică a conformității pentru entitățile esențiale). Mai multe informații privind conținutul legislația NIS2 sunt disponibile pe site-urile nostre (dnsc[.]ro; platformanis2[.]ro). | Y4: Mijlocie | Z4: M | AA4: 2 | AC4: Yes | AD4: HIGH | AE4: ESENȚIAL | AF4: NAȚIONAL | AG4: L | AH4: CRITICĂ RIDICATĂ | AJ4: M | AK4: I | AL4: I | AP4: 102 | AQ4: Transport | AS4: 1012 | AT4: District heating and cooling
B5: No | C5: 50 - 249 | D5: 10 – 50 million € | E5: 10 – 43 million € | F5: Întreprindere mare | G5: Important entity | H5: 2 | J5: Argeș | K5: Pitești | L5: AG | M5: RO331 | N5: =MID(M5,4,2) -> 31 | O5: 11 | Q5: Electricity | S5: 101 | T5: 1011 | W5: În cazul în care vă îndoiți dacă sunteți sau nu în domeniul de aplicare al NIS2, DNSC vă sfătuiește să implementați Cadrul fundamental pentru securitate cibernetică - nivel BASIC (de bază) pentru o primă etapă de asigurare a securității cibernetice la nivelul entității dumneavoastră. Cadrele fundamentale pentru securitate cibernetică (niveluri: BASIC, IMPORTANT și ESENȚIAL) se găsesc pe site-ul instituției (dnsc.ro) și/sau pe PlatformaNIS2 (platformanis2.ro). | Y5: Mare | Z5: L | AA5: 3 | AC5: No | AD5: MEDIUM | AE5: IMPORTANT | AF5: REGIONAL | AG5: M | AH5: CRITICĂ | AP5: 103 | AQ5: Banking | AS5: 1013 | AT5: Oil
B6: N/A | C6: >= 250 | D6: > 50 million € | E6: > 43 million € | F6: Please fill in all 3 criteria that determine the size of the entity and select the size that corresponds to your entity. | G6: Essential entity | H6: 1 | J6: Bacău | K6: Bacău | L6: BC | M6: RO211 | N6: =MID(M6,4,2) -> 11 | O6: 60 | Q6: Electricity undertakings | S6: 101 | T6: 1011 | U6: 101101 | Y6: Vă rugăm să completați toate cele 3 criterii pentru stabilirea dimensiunii entității. | Z6: NA | AA6: 0 | AD6: LOW | AE6: BASIC | AF6: NU | AG6: S | AH6: NON-CRITICĂ | AP6: 104 | AQ6: Financial market infrstructures | AS6: 1014 | AT6: Gas
G7: În afara domeniului de aplicare, înregistrare voluntară | H7: 4 | J7: Bihor | K7: Oradea | L7: BH | M7: RO161 | N7: =MID(M7,4,2) -> 61 | O7: 41 | Q7: Distribution system operators | S7: 101 | T7: 1011 | U7: 101102 | AP7: 105 | AQ7: Health | AS7: 1015 | AT7: Hydrogen
G8: Entitate esențială (Administrație publică) | H8: 3 | J8: Bistrița-Năsăud | K8: Bistrița | L8: BN | M8: RO162 | N8: =MID(M8,4,2) -> 62 | O8: 42 | Q8: Transmission system operators | S8: 101 | T8: 1011 | U8: 101103 | AC8: OUG | AD8: RAȚIUNEA | AK8: VALOARE | AL8: D | AM8: SC | AN8: EVALUARE | AP8: 106 | AQ8: Drinking water | AS8: 1016 | AT8: Beneficiaries of projects financed from non-reimbursable funds
G9: The data entered is insufficient to generate a preliminary assessment. | J9: Botoșani | K9: Botoșani | L9: BT | M9: RO212 | N9: =MID(M9,4,2) -> 12 | O9: 71 | Q9: Electricity producers | S9: 101 | T9: 1011 | U9: 101104 | AC9: 9a | AD9: Singurul furnizor al unui serviciu care este esențial pentru susținerea unor activități societale și economice critice. | AK9: NU | AL9: L | AM9: CRITICĂ RIDICATĂ | AN9: =IF(OR(AK9=AC6,AK9=AC5),"NA",IF(AND(AK9=AC4,AL9=AG4,AM9=AH4),"E",IF(AND(AK9=AC4,OR(AND(AL9=AG5,AM9=AH4),AND(AL9=AG5,AM9=AH5),AND(AL9=AG4,AM9=AH5),AND(AL9=AG6,AM9=AH4),AND(AL9=AG6,AM9=AH5))),"I","NA"))) -> NA | AP9: 107 | AQ9: Waste water | AS9: 1021 | AT9: Air
B10: Cod dimensiune | C10: Dimensiunea | D10: CRITERII | G10: Descriere | J10: Brașov | K10: Brașov | L10: BV | M10: RO172 | N10: =MID(M10,4,2) -> 72 | O10: 50 | Q10: Nominated electricity market operators | S10: 101 | T10: 1011 | U10: 101105 | AC10: 9b | AD10: Perturbarea serviciului furnizat de entitate ar putea avea un impact semnificativ asupra siguranței publice, a securității publice sau a sănătății publice. | AK10: RIDICAT | AL10: L | AM10: CRITICĂ RIDICATĂ | AN10: =IF(OR(AND(AK10=AD4,AL10=AG4,AM10=AH4),AND(AK10=AD5,AL10=AG4,AM10=AH4)),"E",IF(OR(AND(AK10=AD5,OR(AND(AL10=AG5,AM10=AH4),AND(AL10=AG5,AM10=AH5),AND(AL10=AG4,AM10=AH5))),AND(AK10=AD4,OR(AND(AL10=AG5,AM10=AH4),AND(AL10=AG5,AM10=AH5),AND(AL10=AG4,AM10=AH5)))),"I","NA")) -> NA | AP10: 108 | AQ10: Digital Infrstructure | AS10: 1022 | AT10: Rail
D11: Număr mediu salariați | E11: Cifra de afaceri | F11: Total active | J11: Brăila | K11: Brăila | L11: BR | M11: RO221 | N11: =MID(M11,4,2) -> 21 | O11: 81 | Q11: Electricity market participants | S11: 101 | T11: 1011 | U11: 101106 | AC11: 9c | AD11: Perturbarea serviciului furnizat de entitate ar putea genera un risc sistemic semnificativ, în special pentru sectoarele în care o astfel de perturbare ar putea avea un impact transfrontalier; | AK11: RIDICAT | AL11: L | AM11: CRITICĂ RIDICATĂ | AN11: =IF(OR(AND(AK11=AD4,AL11=AG4,AM11=AH4),AND(AK11=AD5,AL11=AG4,AM11=AH4)),"E",IF(OR(AND(AK11=AD5,OR(AND(AL11=AG5,AM11=AH4),AND(AL11=AG5,AM11=AH5),AND(AL11=AG4,AM11=AH5))),AND(AK11=AD4,OR(AND(AL11=AG5,AM11=AH4),AND(AL11=AG5,AM11=AH5),AND(AL11=AG4,AM11=AH5)))),"I","NA")) -> NA | AP11: 109 | AQ11: ICT service management (business-tobusiness) | AS11: 1023 | AT11: Water
B12: - | C12: Micro | D12: 9 | E12: 2000000 | F12: 2000000 | G12: Microîntreprindere | J12: Buzău | K12: Buzău | L12: BZ | M12: RO222 | N12: =MID(M12,4,2) -> 22 | O12: 12 | Q12: Operators of a recharging point | S12: 101 | T12: 1011 | U12: 101107 | AC12: 9d | AD12: Entitatea este critică datorită importanței sale specifice la nivel național sau regional pentru sectorul sau tipul de servicii în cauză sau pentru alte sectoare interdependente. | AK12: NAȚIONAL | AL12: S | AM12: CRITICĂ RIDICATĂ | AN12: =IF(OR(AND(AK12=AF4,AL12=AG4,AM12=AH4),AND(AK12=AF5,AL12=AG4,AM12=AH4)),"E",IF(OR(AND(AK12=AF5,OR(AND(AL12=AG5,AM12=AH4),AND(AL12=AG5,AM12=AH5),AND(AL12=AG4,AM12=AH5))),AND(AK12=AF4,OR(AND(AL12=AG5,AM12=AH4),AND(AL12=AG5,AM12=AH5),AND(AL12=AG4,AM12=AH5)))),"I",IF(AND(AK12=AF4,AL12=AG6,OR(AM12=AH4,AM12=AH5)),"I","NA"))) -> I | AP12: 110 | AQ12: Public administration | AS12: 1024 | AT12: Road
B13: - | C13: Mică | D13: 50 | E13: 10000000 | F13: 10000000 | G13: Întreprindere mică | J13: Caraș-Severin | K13: Caraș-Severin | L13: CS | M13: RO452 | N13: =MID(M13,4,2) -> 52 | O13: 32 | Q13: Economic operators, concessionaires and the developer of the offshore wind turbine | S13: 101 | T13: 1011 | U13: 101108 | AP13: 111 | AQ13: Space | AS13: 1025 | AT13: Public transportation
B14: S | C14: Small and micro | D14: 50 | E14: 10000000 | F14: 10000000 | G14: Întreprindere mică sau microîntreprindere | J14: Călărași | K14: Călărași | L14: CL | M14: RO332 | N14: =MID(M14,4,2) -> 32 | O14: 91 | Q14: District heating and cooling | S14: 101 | T14: 1012 | AP14: 201 | AQ14: Postal and courier services | AS14: 2051 | AT14: Manufacture of medical devices and in vitro diagnostic medical devices
B15: M | C15: Medium | D15: 249 | E15: 50000000 | F15: 43000000 | G15: Întreprindere mijlocie | J15: Cluj | K15: Cluj-Napoca | L15: CJ | M15: RO163 | N15: =MID(M15,4,2) -> 63 | O15: 40 | Q15: Operators of district heating or district cooling | S15: 101 | T15: 1012 | U15: 101201 | AP15: 202 | AQ15: Waste management | AS15: 2052 | AT15: Manufacture of computer, electronic and optical products
B16: L | C16: Large | D16: 250 | E16: 50000000 | F16: 43000000 | G16: Întreprindere mare | J16: Constanța | K16: Constanța | L16: CT | M16: RO223 | N16: =MID(M16,4,2) -> 23 | O16: 90 | Q16: Oil | S16: 101 | T16: 1013 | AP16: 203 | AQ16: Manufacture, production and distribution ofchemicals | AS16: 2053 | AT16: Manufacture of electrical equipment
C17: Select | J17: Covasna | K17: Sfântu Gheorghe | L17: CV | M17: RO173 | N17: =MID(M17,4,2) -> 73 | O17: 52 | Q17: Operators of oil transmission pipelines | S17: 101 | T17: 1013 | U17: 101301 | AP17: 204 | AQ17: Production, processing and distribution of food | AS17: 2054 | AT17: Manufacture of machinery and equipment n.e.c.
B18: Prestator de servicii de încredere | J18: Dâmbovița | K18: Târgoviște | L18: DB | M18: RO333 | N18: =MID(M18,4,2) -> 33 | O18: 13 | Q18: Operators of oil production, refining and treatment facilities, storage and transmission | S18: 101 | T18: 1013 | U18: 101302 | AP18: 205 | AQ18: Manufacturing | AS18: 2055 | AT18: Manufacture of motor vehicles, trailers and semi-trailers
B19: Nu | J19: Dolj | K19: Craiova | L19: DJ | M19: RO441 | N19: =MID(M19,4,2) -> 41 | O19: 20 | Q19: Central stockholding entities | S19: 101 | T19: 1013 | U19: 101303 | AP19: 206 | AQ19: Digital providers | AS19: 2056 | AT19: Manufacture of other transport equipment
B20: Calificat | J20: Galați | K20: Galați | L20: GL | M20: RO224 | N20: =MID(M20,4,2) -> 24 | O20: 80 | Q20: Gas | S20: 101 | T20: 1014 | AP20: 207 | AQ20: Research
B21: Necalificat | J21: Giurgiu | K21: Giurgiu | L21: GR | M21: RO334 | N21: =MID(M21,4,2) -> 34 | O21: 8 | Q21: Natural gas supply undertakings | S21: 101 | T21: 1014 | U21: 101401
J22: Gorj | K22: Târgu Jiu | L22: GJ | M22: RO442 | N22: =MID(M22,4,2) -> 42 | O22: 21 | Q22: Distribution system operators | S22: 101 | T22: 1014 | U22: 101402
J23: Harghita | K23: Miercurea Ciuc | L23: HR | M23: RO174 | N23: =MID(M23,4,2) -> 74 | O23: 53 | Q23: Transmission system operators | S23: 101 | T23: 1014 | U23: 101403
J24: Hunedoara | K24: Deva | L24: HD | M24: RO453 | N24: =MID(M24,4,2) -> 53 | O24: 33 | Q24: Storage system operators | S24: 101 | T24: 1014 | U24: 101404
J25: Ialomița | K25: Slobozia | L25: IL | M25: RO335 | N25: =MID(M25,4,2) -> 35 | O25: 92 | Q25: LNG system operators | S25: 101 | T25: 1014 | U25: 101405
J26: Iași | K26: Iași | L26: IS | M26: RO213 | N26: =MID(M26,4,2) -> 13 | O26: 70 | Q26: Natural gas undertakings | S26: 101 | T26: 1014 | U26: 101406
J27: Ilfov | K27: București | L27: IF | M27: RO382 | N27: =MID(M27,4,2) -> 82 | O27: 7 | Q27: Operators of natural gas refining and treatment facilities | S27: 101 | T27: 1014 | U27: 101407
J28: Maramureș | K28: Baia Mare | L28: MM | M28: RO164 | N28: =MID(M28,4,2) -> 64 | O28: 43 | Q28: Hydrogen | S28: 101 | T28: 1015
J29: Mehedinți | K29: Drobeta Turnu-Severin | L29: MH | M29: RO443 | N29: =MID(M29,4,2) -> 43 | O29: 22 | Q29: Operators of hydrogen production, storage and transmission | S29: 101 | T29: 1015 | U29: 101501
J30: Mureș | K30: Târgu Mureș | L30: MS | M30: RO175 | N30: =MID(M30,4,2) -> 75 | O30: 54 | Q30: Beneficiaries of projects financed from non-reimbursable funds | S30: 101 | T30: 1016
J31: Neamț | K31: Piatra Neamț | L31: NT | M31: RO214 | N31: =MID(M31,4,2) -> 14 | O31: 61 | Q31: Beneficiaries set out in Government Emergency Ordinance No. 60/2022 - Modernization Fund | S31: 101 | T31: 1016 | U31: 101601
J32: Olt | K32: Slatina | L32: OT | M32: RO444 | N32: =MID(M32,4,2) -> 44 | O32: 23 | Q32: TRANSPORT | S32: 102 | T32: 1016
J33: Prahova | K33: Ploiești | L33: PH | M33: RO336 | N33: =MID(M33,4,2) -> 36 | O33: 10 | Q33: Air | S33: 102 | T33: 1021
J34: Satu Mare | K34: Satu Mare | L34: SM | M34: RO165 | N34: =MID(M34,4,2) -> 65 | O34: 44 | Q34: Air carriers | S34: 102 | T34: 1021 | U34: 102101
J35: Sălaj | K35: Zalău | L35: SJ | M35: RO166 | N35: =MID(M35,4,2) -> 66 | O35: 45 | Q35: Airport managing bodies including the core airports and entities operating ancillary installations contained within air ports | S35: 102 | T35: 1021 | U35: 102102
J36: Sibiu | K36: Sibiu | L36: SB | M36: RO176 | N36: =MID(M36,4,2) -> 76 | O36: 55 | Q36: Traffic management control operators providing air traffic control (ATC) services | S36: 102 | T36: 1021 | U36: 102103
J37: Suceava | K37: Suceava | L37: SV | M37: RO215 | N37: =MID(M37,4,2) -> 15 | O37: 72 | Q37: Aircraft maintenance operators | S37: 102 | T37: 1021 | U37: 102104
J38: Teleorman | K38: Alexandria | L38: TR | M38: RO337 | N38: =MID(M38,4,2) -> 37 | O38: 17 | Q38: Civil aviation agents | S38: 102 | T38: 1021 | U38: 102105
J39: Timiș | K39: Timișoara | L39: TM | M39: RO454 | N39: =MID(M39,4,2) -> 54 | O39: 30 | Q39: Organizations referred to in Article 2(1) of Delegated Regulation (EU) 2022/1645 | S39: 102 | T39: 1021 | U39: 102106
J40: Tulcea | K40: Tulcea | L40: TL | M40: RO225 | N40: =MID(M40,4,2) -> 25 | O40: 82 | Q40: Organizations referred to in Article 2(1) of Implementing Regulation (EU) 2023/203 | S40: 102 | T40: 1021 | U40: 102107
...

Sheet Ajutor
B1: Serviciu furnizat | C1: COD | E1: Sector | F1: COD | H1: Sector | I1: COD | K1: Subsector | L1: COD | N1: Subsector | O1: COD
B2: {=_xlfn._xlws.FILTER('Entity assessment'!C30:C142, ('Entity assessment'!D30:D142="Yes") + ('Entity assessment'!D30:D142="Calificat") + ('Entity assessment'!D30:D142="Necalificat"), "")} | C2: =IF(B2="","",VLOOKUP(B2,Liste!Q3:U116,5,FALSE)) | E2: =IF(F2="","",VLOOKUP(Ajutor!F2,Liste!$AP$3:$AQ$20,2,FALSE)) | F2: =IF(C2="","",VALUE(LEFT(TEXT(C2,"000000"),3))) | H2: {=IF(E2="","",_xlfn.UNIQUE(_xlfn._xlws.FILTER(E2:F6,(E2:E6<>"")*(F2:F6<>""))))} | K2: =IF(L2="","",VLOOKUP(Ajutor!L2,Liste!$AS$3:$AT$19,2,FALSE)) | L2: =IF(C2="","",IF(MID(TEXT(C2,"000000"),4,1)<>"0",VALUE(LEFT(TEXT(C2,"000000"),4)),"")) | N2: {=IF(K2="","",_xlfn.UNIQUE(_xlfn._xlws.FILTER(K2:L6,(L2:L6<>"")*(L2:L6<>""))))}
C3: =IF(B3="","",VLOOKUP(B3,Liste!Q4:U117,5,FALSE)) | E3: =IF(F3="","",VLOOKUP(Ajutor!F3,Liste!$AP$3:$AQ$20,2,FALSE)) | F3: =IF(C3="","",VALUE(LEFT(TEXT(C3,"000000"),3))) | K3: =IF(L3="","",VLOOKUP(Ajutor!L3,Liste!$AS$3:$AT$19,2,FALSE)) | L3: =IF(C3="","",IF(MID(TEXT(C3,"000000"),4,1)<>"0",VALUE(LEFT(TEXT(C3,"000000"),4)),""))
C4: =IF(B4="","",VLOOKUP(B4,Liste!Q5:U118,5,FALSE)) | E4: =IF(F4="","",VLOOKUP(Ajutor!F4,Liste!$AP$3:$AQ$20,2,FALSE)) | F4: =IF(C4="","",VALUE(LEFT(TEXT(C4,"000000"),3))) | K4: =IF(L4="","",VLOOKUP(Ajutor!L4,Liste!$AS$3:$AT$19,2,FALSE)) | L4: =IF(C4="","",IF(MID(TEXT(C4,"000000"),4,1)<>"0",VALUE(LEFT(TEXT(C4,"000000"),4)),""))
C5: =IF(B5="","",VLOOKUP(B5,Liste!Q6:U119,5,FALSE)) | E5: =IF(F5="","",VLOOKUP(Ajutor!F5,Liste!$AP$3:$AQ$20,2,FALSE)) | F5: =IF(C5="","",VALUE(LEFT(TEXT(C5,"000000"),3))) | K5: =IF(L5="","",VLOOKUP(Ajutor!L5,Liste!$AS$3:$AT$19,2,FALSE)) | L5: =IF(C5="","",IF(MID(TEXT(C5,"000000"),4,1)<>"0",VALUE(LEFT(TEXT(C5,"000000"),4)),""))
C6: =IF(B6="","",VLOOKUP(B6,Liste!Q7:U120,5,FALSE)) | E6: =IF(F6="","",VLOOKUP(Ajutor!F6,Liste!$AP$3:$AQ$20,2,FALSE)) | F6: =IF(C6="","",VALUE(LEFT(TEXT(C6,"000000"),3))) | K6: =IF(L6="","",VLOOKUP(Ajutor!L6,Liste!$AS$3:$AT$19,2,FALSE)) | L6: =IF(C6="","",IF(MID(TEXT(C6,"000000"),4,1)<>"0",VALUE(LEFT(TEXT(C6,"000000"),4)),""))
C7: =IF(B7="","",VLOOKUP(B7,Liste!Q8:U121,5,FALSE))
C8: =IF(B8="","",VLOOKUP(B8,Liste!Q9:U122,5,FALSE))
C9: =IF(B9="","",VLOOKUP(B9,Liste!Q10:U123,5,FALSE))
C10: =IF(B10="","",VLOOKUP(B10,Liste!Q11:U124,5,FALSE))
C11: =IF(B11="","",VLOOKUP(B11,Liste!Q12:U125,5,FALSE))
C12: =IF(B12="","",VLOOKUP(B12,Liste!Q13:U126,5,FALSE))
C13: =IF(B13="","",VLOOKUP(B13,Liste!Q14:U127,5,FALSE))
C14: =IF(B14="","",VLOOKUP(B14,Liste!Q15:U128,5,FALSE))
C15: =IF(B15="","",VLOOKUP(B15,Liste!Q16:U129,5,FALSE))
C16: =IF(B16="","",VLOOKUP(B16,Liste!Q17:U130,5,FALSE))
C17: =IF(B17="","",VLOOKUP(B17,Liste!Q18:U131,5,FALSE))
C18: =IF(B18="","",VLOOKUP(B18,Liste!Q19:U132,5,FALSE))

Sheet Algoritm clasificare
B1: prioritate | C1: Anexa 1 | E1: Condiție specială | F1: Mică și micro | H1: Mijlociu | J1: Mare | L1: Important | M1: Esențial
C2: =IF('Entity assessment'!D111="Yes", 1, 0) -> 0 | D2: Administrație Publică Centrală RO | E2: D160 | F2: Esențial | H2: Esențial | J2: Esențial | L2: =IF(AND(M2=0, OR(G6=1,I5=1, I9=1, K11=1, K12=1, I8=1)), 1, 0) -> 0 | M2: =IF(OR(K3=1,K5=1, K4=1, K8=1, K9=1, K6=1, K7=1, 'Entity assessment'!D153="Yes", AND(C2=1, 'Entity assessment'!D152="Yes") ), 1, 0) -> 0
B3: 1 | C3: =IF('Entity assessment'!D104="Yes", 1, 0) -> 0 | D3: Prestatori calificati | F3: Esențial | H3: Esențial | J3: Esențial | K3: =IF(AND(C3=1, 'Entity assessment'!D150="Yes"), 1, 0) -> 0
B4: 2 | C4: =IF( COUNTIF('Entity assessment'!D98,"Yes") +COUNTIF('Entity assessment'!D99,"Yes")>0, 1,0) -> 0 | D4: DNS, TLD | F4: Esențial | H4: Esențial | J4: Esențial | K4: =IF(AND(C4=1, 'Entity assessment'!D151="Yes"), 1, 0) -> 0
B5: 3 | C5: =IF('Entity assessment'!D103="Yes", 1, 0) -> 0 | D5: Prestatorii necalificati | F5: Important | H5: Important | I5: =IF(AND(C5=1, OR('Entity assessment'!D21="Small and micro", 'Entity assessment'!D21="Medium"), 'Entity assessment'!D150="Yes"), 1, 0) -> 0 | J5: Esențial | K5: =IF(AND(C5=1, 'Entity assessment'!D21="Large", 'Entity assessment'!D150="Yes"), 1, 0) -> 0
B6: 4 | C6: =IF( COUNTIF('Entity assessment'!D105,"Yes") +COUNTIF('Entity assessment'!D106,"Yes")>0, 1,0) -> 0 | D6: Telecomunicații | F6: Important | G6: =IF(AND(C6=1, 'Entity assessment'!D21="Small and micro", 'Entity assessment'!D159="Yes"), 1, 0) -> 0 | H6: Esențial | J6: Esențial | K6: =IF(AND(C6=1, OR('Entity assessment'!D21="Large", 'Entity assessment'!D21="Medium"), 'Entity assessment'!D159="Yes"), 1, 0) -> 0
B7: 6 | C7: =IF( COUNTIF('Entity assessment'!D109,"Yes")>0, 1,0) -> 0 | D7: MSSP | K7: =IF(AND(C7=1, OR('Entity assessment'!D22="Large", 'Entity assessment'!D22="Medium"), 'Entity assessment'!D151="Yes"), 1, 0) -> 0
B8: 3 | C8: =IF( COUNTIF('Entity assessment'!D100,"Yes") +COUNTIF('Entity assessment'!D101,"Yes") +COUNTIF('Entity assessment'!D102,"Yes") +COUNTIF('Entity assessment'!D108,"Yes")>0, 1,0) -> 0 | D8: furnizorii de servicii de cloud computing, furnizorii de servicii de centre de date, furnizorii de rețele de furnizare de conținut, furnizorii de servicii gestionate | F8: Art.9 | G8: =IF(AND(C8=1, 'Entity assessment'!D21="Small and micro", 'Entity assessment'!D151="Yes"), 1, 0) -> 0 | H8: Important | I8: =IF(AND(C8=1, 'Entity assessment'!D21="Medium", 'Entity assessment'!D151="Yes"), 1, 0) -> 0 | J8: Esențial | K8: =IF(AND(C8=1, 'Entity assessment'!D21="Large", 'Entity assessment'!D151="Yes"), 1, 0) -> 0
B9: 4 | C9: =IF( COUNTIF('Entity assessment'!D31:D56,"Yes") +COUNTIF('Entity assessment'!D59:D77,"Yes") +COUNTIF('Entity assessment'!D79:D83,"Yes") +COUNTIF('Entity assessment'!D85:D97,"Yes") +COUNTIF('Entity assessment'!D113,"Yes")>0, 1,0) -> 0 | D9: energie, transport, bancar, financiar, sanatate, potabila, uzate, spațial, IXP | F9: Art. 9 | H9: Important | I9: =IF(AND(C9=1, 'Entity assessment'!D21="Medium", 'Entity assessment'!D150="Yes"), 1, 0) -> 0 | J9: Esențial | K9: =IF(AND(C9=1, 'Entity assessment'!D21="Large", 'Entity assessment'!D150="Yes"), 1, 0) -> 0
C10: Anexa 2
B11: 7 | C11: =IF( COUNTIF('Entity assessment'!D116:D135,"Yes") + COUNTIF('Entity assessment'!D141,"Yes")> 0, 1, 0) -> 0 | D11: Toate din Anexa 2 | H11: Important | J11: Important | K11: =IF(AND(C11=1, OR('Entity assessment'!D21="Large", 'Entity assessment'!D21="Medium"), 'Entity assessment'!D150="Yes"), 1, 0) -> 0
B12: 8 | C12: =IF( COUNTIF('Entity assessment'!D137,"Yes") +COUNTIF('Entity assessment'!D138,"Yes") +COUNTIF('Entity assessment'!D139,"Yes")>0, 1, 0) -> 0 | D12: furnizorii de piețe online, de motoare de căutare online și de platforme de servicii de socializare în rețea | K12: =IF(AND(C11=1, OR('Entity assessment'!D21="Large", 'Entity assessment'!D21="Medium"), 'Entity assessment'!D151="Yes"), 1, 0) -> 0
B13: Art 9
D14: Art. 9 la C4 | L14: =IF(AND(G8=1, M2=0, M14=0, OR('Entity assessment'!D170="MEDIUM", 'Entity assessment'!D171="MEDIUM")), 1, 0) -> 0 | M14: =IF(AND(C8=1, M2=0, 'Entity assessment'!D151="Yes", OR('Entity assessment'!D169="Yes", 'Entity assessment'!D172="Yes", 'Entity assessment'!D170="HIGH", 'Entity assessment'!D171="HIGH")), 1, 0) -> 0
B15: prio5 | D15: Art. 9 la C7 și C9 | L15: =IF(AND(OR(C9=1, C7=1), M15=0, M2=0, 'Entity assessment'!D150="Yes", OR('Entity assessment'!D170="MEDIUM", 'Entity assessment'!D171="MEDIUM")), 1, 0) -> 0 | M15: =IF(AND(OR(C9=1, C7=1), M2=0, 'Entity assessment'!D150="Yes", OR('Entity assessment'!D169="Yes", 'Entity assessment'!D172="Yes", 'Entity assessment'!D170="HIGH", 'Entity assessment'!D171="HIGH")), 1, 0) -> 0
B16: prio6 | D16: 1 | L16: =IF(AND(C11=1, M16=0, 'Entity assessment'!D150="Yes", OR('Entity assessment'!D169="Yes", 'Entity assessment'!D170="MEDIUM", 'Entity assessment'!D170="HIGH", 'Entity assessment'!D171="MEDIUM", 'Entity assessment'!D171="HIGH"), SUM(K3:M15)=0 ), 1, 0) -> 0 | M16: =IF(AND(C11=1, 'Entity assessment'!D172="Yes", 'Entity assessment'!D150="Yes"), 1, 0) -> 0
E17: D158 - Înregistrat în RO | F17: D159 - Sediul principal în RO | G17: D160 - Este înființată de Ro | H17: D167 - Furnizează servicii în RO | I17: Lipsă dimensiune | J17: Blocaj art. 9 | L17: =IF(AND(C12=1, M17=0, L2=0, M2=0, 'Entity assessment'!D151="Da", OR('Entity assessment'!D170="MEDIU", 'Entity assessment'!D169="Da", 'Entity assessment'!D170="RIDICAT", 'Entity assessment'!D171="RIDICAT", 'Entity assessment'!D171="MEDIU")), 1, 0) -> 0 | M17: =IF(AND(C12=1, 'Entity assessment'!D172="Da", 'Entity assessment'!D151="Da"), 1, 0) -> 0
D18: Blocare | E18: =IF(AND( OR(C2=1, C3=1, C4=1, C5=1, C7=1, C8=1, C9=1, C11=1, C12=1), 'Entity assessment'!D150="Select" ), 1, 0) -> 0 | F18: =IF(AND( OR(C4=1, C7=1, C8=1, C12=1), 'Entity assessment'!D151="Select" ), 1, 0) -> 0 | G18: =IF(AND(C2=1, 'Entity assessment'!D152="Select"), 1, 0) -> 0 | H18: =IF(AND(OR(C6=1, C4=1), 'Entity assessment'!D159="Select"), 1, 0) -> 0 | I18: =IF(AND(OR(C5=1, C6=1, C7=1, C8=1, C9=1, C11=1, C12=1), 'Entity assessment'!D21="Select"), 1, 0) -> 0 | J18: =IF(AND('Entity assessment'!C166="Perform the impact assessment in accordance with DNSC Director's Order No. 2/2025.", OR('Entity assessment'!D169="Select", 'Entity assessment'!D170="Select", 'Entity assessment'!D171="Select", 'Entity assessment'!D172="Select")), 1, 0) -> 0
